Workbook

Sheet Wilcoxon
A1: Wilcoxon signed-rank test (L2) | C1: p | D1: p | E1: p | F1: p | G1: p
A2: first factor | B2: second factor | C2: RF | D2: Retuned RF | E2: DT | F2: GBR | G2: RF Retest
A3: 0 | B3: 0.25 | C3: 0.65682208 | D3: 0.215923 | E3: 0.00017560038 | F3: 0.6159946 | G3: 0.58783197
A4: 0 | B4: 0.5 | C4: 0.59353336 | D4: 3.3383463e-06 | E4: 0.56398797 | F4: 2.5283722e-08 | G4: 0.29765191
A5: 0 | B5: 0.75 | C5: 0.0034791526 | D5: 0.0062734341 | E5: 0.61124979 | F5: 0.84725013 | G5: 0.0011607407
A6: 0 | B6: 1 | C6: 2.6957415e-10 | D6: 2.691172e-10 | E6: 0.00080181537 | F6: 1.4150641e-08 | G6: 1.300222e-11
A7: 0.25 | B7: 0.5 | C7: 0.85161714 | D7: 3.3383463e-06 | E7: 2.4968263e-12 | F7: 3.9211973e-12 | G7: 0.027153528
A8: 0.25 | B8: 0.75 | C8: 8.5817161e-05 | D8: 0.0047599362 | E8: 0.00016263781 | F8: 0.92738973 | G8: 0.00032664985
A9: 0.5 | B9: 0.75 | C9: 3.4747263e-11 | D9: 8.9039188e-12 | E9: 9.8050269e-12 | F9: 5.68533e-08 | G9: 5.0775068e-12
A10: 1 | B10: 0.25 | C10: 0.00052627362 | D10: 0.0083895423 | E10: 0.046084241 | F10: 2.2701674e-11 | G10: 0.16050586
A11: 1 | B11: 0.5 | C11: 1.6634122e-11 | D11: 3.1415253e-11 | E11: 9.260491e-08 | F11: 3.136838e-13 | G11: 7.6438298e-11
A12: 1 | B12: 0.75 | C12: 1.6164567e-07 | D12: 4.9836337e-11 | E12: 1.5441489e-05 | F12: 5.4521146e-13 | G12: 9.4228138e-08
A17: Factor | B17: RF | C17: Retuned RF | D17: DT | E17: GBR | F17: RF Retest
A18: 0-25% | B18: 0.65682208 | C18: 0.215923 | D18: 0.00017560038 | E18: 0.6159946 | F18: 0.58783197 | G18: =COUNTIF(B18:F18,"<0.01") -> 1
A19: 0-50% | B19: 0.59353336 | C19: 3.3383463e-06 | D19: 0.56398797 | E19: 2.5283722e-08 | F19: 0.29765191 | G19: =COUNTIF(B19:F19,"<0.01") -> 2
A20: 0-75% | B20: 0.0034791526 | C20: 0.0062734341 | D20: 0.61124979 | E20: 0.84725013 | F20: 0.0011607407 | G20: =COUNTIF(B20:F20,"<0.01") -> 3
A21: 0-100% | B21: 2.6957415e-10 | C21: 2.691172e-10 | D21: 0.00080181537 | E21: 1.4150641e-08 | F21: 1.300222e-11 | G21: =COUNTIF(B21:F21,"<0.01") -> 5
A22: 25-50% | B22: 0.85161714 | C22: 3.3383463e-06 | D22: 2.4968263e-12 | E22: 3.9211973e-12 | F22: 0.027153528 | G22: =COUNTIF(B22:F22,"<0.01") -> 3
A23: 25-75% | B23: 8.5817161e-05 | C23: 0.0047599362 | D23: 0.00016263781 | E23: 0.92738973 | F23: 0.00032664985 | G23: =COUNTIF(B23:F23,"<0.01") -> 4
A24: 25-100% | B24: 0.00052627362 | C24: 0.0083895423 | D24: 0.046084241 | E24: 2.2701674e-11 | F24: 0.16050586 | G24: =COUNTIF(B24:F24,"<0.01") -> 3
A25: 50-75% | B25: 3.4747263e-11 | C25: 8.9039188e-12 | D25: 9.8050269e-12 | E25: 5.68533e-08 | F25: 5.0775068e-12 | G25: =COUNTIF(B25:F25,"<0.01") -> 5
A26: 50-100% | B26: 1.6634122e-11 | C26: 3.1415253e-11 | D26: 9.260491e-08 | E26: 3.136838e-13 | F26: 7.6438298e-11 | G26: =COUNTIF(B26:F26,"<0.01") -> 5
A27: 75-100% | B27: 1.6164567e-07 | C27: 4.9836337e-11 | D27: 1.5441489e-05 | E27: 5.4521146e-13 | F27: 9.4228138e-08 | G27: =COUNTIF(B27:F27,"<0.01") -> 5

Sheet Stratified Wilcoxon
A1: Stratitfied Wilcoxon (L2) | C1: p | D1: p | E1: p | F1: p | G1: p
A2: first factor | B2: second factor | C2: RF | D2: Retuned RF | E2: DT | F2: GBR | G2: RF Retest
A3: 0 | B3: 0.25 | C3: 0.20983671 | D3: 0.7558037 | E3: 5.8364962e-05 | F3: 0.87386767 | G3: 0.73000318
A4: 0 | B4: 0.5 | C4: 0.35881143 | D4: 1.0442058e-06 | E4: 0.0060637307 | F4: 3.7919579e-10 | G4: 0.35814691
A5: 0 | B5: 0.75 | C5: 0.0048390353 | D5: 0.18687573 | E5: 0.87765086 | F5: 0.38656186 | G5: 0.04058976
A6: 0 | B6: 1 | C6: 7.4747924e-09 | D6: 1.6951797e-09 | E6: 0.87765086 | F6: 5.5159163e-09 | G6: 4.1192235e-10
A7: 0.25 | B7: 0.5 | C7: 0.74193058 | D7: 5.7997761e-06 | E7: 3.8074432e-10 | F7: 1.642575e-11 | G7: 0.04058976
A8: 0.25 | B8: 0.75 | C8: 9.978733e-06 | D8: 0.19871366 | E8: 0.0060637307 | F8: 0.39340611 | G8: 0.01274984
A9: 0.5 | B9: 0.75 | C9: 1.0664292e-09 | D9: 1.3057999e-10 | E9: 3.749482e-14 | F9: 6.649818e-08 | G9: 2.4429347e-11
A10: 1 | B10: 0.25 | C10: 6.0819668e-05 | D10: 0.00062644889 | E10: 0.13090454 | F10: 2.8713978e-12 | G10: 0.092813439
A11: 1 | B11: 0.5 | C11: 1.0664292e-09 | D11: 4.0638604e-10 | E11: 1.4895203e-10 | F11: 1.110223e-14 | G11: 4.1192235e-10
A12: 1 | B12: 0.75 | C12: 7.2917401e-06 | D12: 8.6860001e-10 | E12: 0.03141875 | F12: 1.8351987e-12 | G12: 5.9415293e-08
A14: Stratified Wilcoxon
A15: Factor | B15: RF | C15: Retuned RF | D15: DT | E15: GBR | F15: RF Retest
A16: 0-25% | B16: 0.20983671 | C16: 0.7558037 | D16: 5.8364962e-05 | E16: 0.87386767 | F16: 0.73000318
A17: 0-50% | B17: 0.35881143 | C17: 1.0442058e-06 | D17: 0.0060637307 | E17: 3.7919579e-10 | F17: 0.35814691
A18: 0-75% | B18: 0.0048390353 | C18: 0.18687573 | D18: 0.87765086 | E18: 0.38656186 | F18: 0.04058976
A19: 0-100% | B19: 7.4747924e-09 | C19: 1.6951797e-09 | D19: 0.87765086 | E19: 5.5159163e-09 | F19: 4.1192235e-10
A20: 25-50% | B20: 0.74193058 | C20: 5.7997761e-06 | D20: 3.8074432e-10 | E20: 1.642575e-11 | F20: 0.04058976
A21: 25-75% | B21: 9.978733e-06 | C21: 0.19871366 | D21: 0.0060637307 | E21: 0.39340611 | F21: 0.01274984
A22: 25-100% | B22: 1.0664292e-09 | C22: 1.3057999e-10 | D22: 3.749482e-14 | E22: 6.649818e-08 | F22: 2.4429347e-11
A23: 50-75% | B23: 6.0819668e-05 | C23: 0.00062644889 | D23: 0.13090454 | E23: 2.8713978e-12 | F23: 0.092813439
A24: 50-100% | B24: 1.0664292e-09 | C24: 4.0638604e-10 | D24: 1.4895203e-10 | E24: 1.110223e-14 | F24: 4.1192235e-10
A25: 75-100% | B25: 7.2917401e-06 | C25: 8.6860001e-10 | D25: 0.03141875 | E25: 1.8351987e-12 | F25: 5.9415293e-08
A26: Wilcoxon
A27: Factor | B27: RF | C27: Retuned RF | D27: DT | E27: GBR | F27: RF Retest
A28: 0-25% | B28: 0.65682208 | C28: 0.215923 | D28: 0.00017560038 | E28: 0.6159946 | F28: 0.58783197
A29: 0-50% | B29: 0.59353336 | C29: 3.3383463e-06 | D29: 0.56398797 | E29: 2.5283722e-08 | F29: 0.29765191
A30: 0-75% | B30: 0.0034791526 | C30: 0.0062734341 | D30: 0.61124979 | E30: 0.84725013 | F30: 0.0011607407
A31: 0-100% | B31: 2.6957415e-10 | C31: 2.691172e-10 | D31: 0.00080181537 | E31: 1.4150641e-08 | F31: 1.300222e-11
A32: 25-50% | B32: 0.85161714 | C32: 3.3383463e-06 | D32: 2.4968263e-12 | E32: 3.9211973e-12 | F32: 0.027153528
A33: 25-75% | B33: 8.5817161e-05 | C33: 0.0047599362 | D33: 0.00016263781 | E33: 0.92738973 | F33: 0.00032664985
A34: 25-100% | B34: 0.00052627362 | C34: 0.0083895423 | D34: 0.046084241 | E34: 2.2701674e-11 | F34: 0.16050586
A35: 50-75% | B35: 3.4747263e-11 | C35: 8.9039188e-12 | D35: 9.8050269e-12 | E35: 5.68533e-08 | F35: 5.0775068e-12
A36: 50-100% | B36: 1.6634122e-11 | C36: 3.1415253e-11 | D36: 9.260491e-08 | E36: 3.136838e-13 | F36: 7.6438298e-11
A37: 75-100% | B37: 1.6164567e-07 | C37: 4.9836337e-11 | D37: 1.5441489e-05 | E37: 5.4521146e-13 | F37: 9.4228138e-08

Sheet Bootstrap
A1: Median Diff. (L2) | C1: RF | G1: Retuned RF | K1: DT | O1: GBR | S1: RF Retest
A2: First Factor | B2: Second Factor | C2: Effect Size | D2: % Change | E2: p | F2: CI | G2: Effect Size | H2: % Change | I2: p | J2: CI | K2: Effect Size | L2: % Change | M2: p | N2: CI | O2: Effect Size | P2: % Change | Q2: p | R2: CI | S2: Effect Size | T2: % Change | U2: p | V2: CI
A3: 0 | B3: 0.25 | C3: 6.4619302e-05 | D3: 6.7740063e-06 | E3: 0.95540446 | F3: [-0.003, 0.001] | G3: 0.0003919685 | H3: 3.2692937e-05 | I3: 0.64783522 | J3: [-0.002, 0.002] | K3: 0.076026311 | L3: 0.0073297654 | M3: 0.0099990001 | N3: [0.030, 0.098] | O3: -0.0012454149 | P3: -0.00018689723 | Q3: 0.91630837 | R3: [-0.010, 0.017] | S3: -0.0016119878 | T3: -0.00020441031 | U3: 0.5180482 | V3: [-0.006, 0.004]
A4: 0 | B4: 0.5 | C4: -0.0013480512 | D4: -0.0001424106 | E4: 0.20977902 | F4: [-0.003, 0.001] | G4: -0.007041741 | H4: -0.00062331638 | I4: 9.9990001e-05 | J4: [-0.009, -0.005] | K4: 0.020838699 | L4: 0.009472136 | M4: 0.10348965 | N4: [0.015, 0.022] | O4: -0.035385484 | P4: -0.011807742 | Q4: 9.9990001e-05 | R4: [-0.044, -0.030] | S4: -0.0011089503 | T4: -0.00013366349 | U4: 0.57364264 | V4: [-0.004, 0.004]
A5: 0 | B5: 0.75 | C5: 0.001498911 | D5: 0.00014682832 | E5: 0.1729827 | F5: [-0.001, 0.005] | G5: -0.0021921424 | H5: -0.00018159505 | I5: 0.01389861 | J5: [-0.005, -0.000] | K5: 0 | L5: 0 | M5: 1 | N5: [0.000, 0.000] | O5: -0.0049420048 | P5: -0.00070695679 | Q5: 0.35126487 | R5: [-0.011, 0.007] | S5: 0.0054855669 | T5: 0.00068530738 | U5: 0.01229877 | V5: [-0.001, 0.010]
A6: 0 | B6: 1 | C6: 0.014672054 | D6: 0.0014148421 | E6: 9.9990001e-05 | F6: [0.010, 0.019] | G6: 0.0080974702 | H6: 0.00064135 | I6: 9.9990001e-05 | J6: [0.006, 0.011] | K6: 0 | L6: 0 | M6: 1 | N6: [0.000, 0.000] | O6: 0.029764994 | P6: 0.0030025868 | Q6: 9.9990001e-05 | R6: [0.017, 0.042] | S6: 0.011217631 | T6: 0.0012082819 | U6: 9.9990001e-05 | V6: [0.009, 0.016]
A7: 0.25 | B7: 0.5 | C7: -7.7060894e-05 | D7: -8.1408541e-06 | E7: 0.84951505 | F7: [-0.002, 0.001] | G7: -0.0067753348 | H7: -0.0005997348 | I7: 9.9990001e-05 | J7: [-0.010, -0.005] | K7: -0.08551744 | L7: -0.038871564 | M7: 9.9990001e-05 | N7: [-0.091, -0.076] | O7: -0.03112258 | P7: -0.010385258 | Q7: 9.9990001e-05 | R7: [-0.044, -0.027] | S7: 0.0021810228 | T7: 0.00026288204 | U7: 0.0055994401 | V7: [0.001, 0.004]
A8: 0.25 | B8: 0.75 | C8: 0.0035019586 | D8: 0.00034304018 | E8: 0.00059994001 | F8: [0.001, 0.005] | G8: -0.0037187137 | H8: -0.0003080548 | I8: 0.056494351 | J8: [-0.007, 0.001] | K8: -0.06918392 | L8: -6.918392e+08 | M8: 9.9990001e-05 | N8: [-0.079, 0.000] | O8: 0.0060072936 | P8: 0.000859347 | Q8: 0.39836016 | R8: [-0.007, 0.014] | S8: 0.003130718 | T8: 0.00039111802 | U8: 0.00049995 | V8: [0.001, 0.006]
A9: 0.25 | B9: 1 | C9: 0.0025763255 | D9: 0.00025236825 | E9: 0.00029997 | F9: [0.001, 0.005] | G9: 0.0036902638 | H9: 0.00030569803 | I9: 0.0063993601 | J9: [0.001, 0.007] | K9: -0.018820161 | L9: -1.8820161e+08 | M9: 0.32616738 | N9: [-0.022, 0.071] | O9: 0.039114734 | P9: 0.0055953865 | Q9: 9.9990001e-05 | R9: [0.027, 0.043] | S9: 0.0011652409 | T9: 0.00014557259 | U9: 0.1979802 | V9: [-0.001, 0.004]
A10: 0.5 | B10: 1 | C10: 0.011318069 | D10: 0.0010914137 | E10: 9.9990001e-05 | F10: [0.010, 0.015] | G10: 0.014738378 | H10: 0.0011673348 | I10: 9.9990001e-05 | J10: [0.011, 0.016] | K10: -0.022 | L10: -220000000 | M10: 9.9990001e-05 | N10: [-0.022, -0.010] | O10: 0.069053581 | P10: 0.0069658798 | Q10: 9.9990001e-05 | R10: [0.062, 0.077] | S10: 0.010828138 | T10: 0.0011663285 | U10: 9.9990001e-05 | V10: [0.008, 0.014]
A11: 0.5 | B11: 0.75 | C11: 0.012445664 | D11: 0.0012001489 | E11: 9.9990001e-05 | F11: [0.009, 0.016] | G11: 0.0073939576 | H11: 0.00058562917 | I11: 9.9990001e-05 | J11: [0.007, 0.008] | K11: -0.098149546 | L11: -9.8149546e+08 | M11: 9.9990001e-05 | N11: [-0.100, -0.096] | O11: 0.043474323 | P11: 0.0043855352 | Q11: 9.9990001e-05 | R11: [0.032, 0.048] | S11: 0.012695753 | T11: 0.0013674944 | U11: 9.9990001e-05 | V11: [0.008, 0.015]
A12: 0.75 | B12: 1 | C12: 0.0074007353 | D12: 0.00071366095 | E12: 9.9990001e-05 | F12: [0.004, 0.014] | G12: 0.0095925879 | H12: 0.00075976893 | I12: 9.9990001e-05 | J12: [0.006, 0.014] | K12: 0 | L12: 0 | M12: 1 | N12: [0.000, 0.000] | O12: 0.035832684 | P12: 0.0036146737 | Q12: 9.9990001e-05 | R12: [0.027, 0.040] | S12: 0.0076173318 | T12: 0.00082048374 | U12: 9.9990001e-05 | V12: [0.005, 0.011]
A16: Median Diff. (L2)
A17: First Factor | B17: RF | C17: Retuned RF | D17: DT | E17: GBR | F17: RF Retest
A18: =A3&"-"&B3 -> 0-0.25 | B18: =D3 -> 6.7740063e-06 | C18: =H3 -> 3.2692937e-05 | D18: =L3 -> 0.0073297654 | E18: =P3 -> -0.00018689723 | F18: =T3 -> -0.00020441031
A19: =A4&"-"&B4 -> 0-0.5 | B19: =D4 -> -0.0001424106 | C19: =H4 -> -0.00062331638 | D19: =L4 -> 0.009472136 | E19: =P4 -> -0.011807742 | F19: =T4 -> -0.00013366349
A20: =A5&"-"&B5 -> 0-0.75 | B20: =D5 -> 0.00014682832 | C20: =H5 -> -0.00018159505 | D20: =L5 -> 0 | E20: =P5 -> -0.00070695679 | F20: =T5 -> 0.00068530738
A21: =A6&"-"&B6 -> 0-1 | B21: =D6 -> 0.0014148421 | C21: =H6 -> 0.00064135 | D21: =L6 -> 0 | E21: =P6 -> 0.0030025868 | F21: =T6 -> 0.0012082819
A29: Median Diff. (L2) | C29: RF | G29: Retuned RF | K29: DT | O29: GBR | S29: RF Retest
A30: First Factor | B30: Second Factor | C30: Effect Size | D30: % Change | E30: p | F30: CI | G30: Effect Size | H30: % Change | I30: p | J30: CI | K30: Effect Size | L30: % Change | M30: p | N30: CI | O30: Effect Size | P30: % Change | Q30: p | R30: CI | S30: Effect Size | T30: % Change | U30: p | V30: CI
A31: 0 | B31: 0.25 | C31: 6.4619302e-05 | D31: 6.7740063e-06 | E31: 0.95540446 | F31: [-0.003, 0.001] | G31: 0.0003919685 | H31: 3.2692937e-05 | I31: 0.64783522 | J31: [-0.002, 0.002] | K31: 0.076026311 | L31: 0.0073297654 | M31: 0.0099990001 | N31: [0.030, 0.098] | O31: -0.0012454149 | P31: -0.00018689723 | Q31: 0.91630837 | R31: [-0.010, 0.017] | S31: 6.4619302e-05 | T31: 6.7740063e-06 | U31: 0.95540446 | V31: [-0.003, 0.001]
A32: 0 | B32: 0.5 | C32: -0.0013480512 | D32: -0.0001424106 | E32: 0.20977902 | F32: [-0.003, 0.001] | G32: -0.007041741 | H32: -0.00062331638 | I32: 9.9990001e-05 | J32: [-0.009, -0.005] | K32: 0.020838699 | L32: 0.009472136 | M32: 0.10348965 | N32: [0.015, 0.022] | O32: -0.035385484 | P32: -0.011807742 | Q32: 9.9990001e-05 | R32: [-0.044, -0.030] | S32: -0.0013480512 | T32: -0.0001424106 | U32: 0.20977902 | V32: [-0.003, 0.001]
A33: 0 | B33: 0.75 | C33: 0.001498911 | D33: 0.00014682832 | E33: 0.1729827 | F33: [-0.001, 0.005] | G33: -0.0021921424 | H33: -0.00018159505 | I33: 0.01389861 | J33: [-0.005, -0.000] | K33: 0 | L33: 0 | M33: 1 | N33: [0.000, 0.000] | O33: -0.0049420048 | P33: -0.00070695679 | Q33: 0.35126487 | R33: [-0.011, 0.007] | S33: 0.001498911 | T33: 0.00014682832 | U33: 0.1729827 | V33: [-0.001, 0.005]
A34: 0 | B34: 1 | C34: 0.014672054 | D34: 0.0014148421 | E34: 9.9990001e-05 | F34: [0.010, 0.019] | G34: 0.0080974702 | H34: 0.00064135 | I34: 9.9990001e-05 | J34: [0.006, 0.011] | K34: 0 | L34: 0 | M34: 1 | N34: [0.000, 0.000] | O34: 0.029764994 | P34: 0.0030025868 | Q34: 9.9990001e-05 | R34: [0.017, 0.042] | S34: 0.014672054 | T34: 0.0014148421 | U34: 9.9990001e-05 | V34: [0.010, 0.019]
A37: Factor | B37: RF | C37: Retuned RF | D37: DT | E37: GBR | F37: RF Retest
A38: 0-25% | B38: 0.000 [-0.003, 0.001]; .657 | C38: 0.000 [-0.002, 0.002]; .216 | D38: 0.076 [0.030, 0.098]; .000 | E38: -0.001 [-0.010, 0.017]; .616 | F38: -0.002 [-0.006, 0.004]; .588
A39: 0-50% | B39: -0.001 [-0.003, 0.001]; .594 | C39: -0.007 [-0.009, -0.005]; .000 | D39: 0.021 [0.015, 0.022]; .564 | E39: -0.035 [-0.044, -0.030]; .000 | F39: -0.001 [-0.004, 0.004]; .298
A40: 0-75% | B40: 0.001 [-0.001, 0.005]; .003 | C40: -0.002 [-0.005, -0.000]; .006 | D40: 0.000 [0.000, 0.000]; .611 | E40: -0.005 [-0.011, 0.007]; .847 | F40: 0.005 [-0.001, 0.010]; .001
A41: 0-100% | B41: 0.015 [0.010, 0.019]; .000 | C41: 0.008 [0.006, 0.011]; .000 | D41: 0.000 [0.000, 0.000]; .001 | E41: 0.030 [0.017, 0.042]; .000 | F41: 0.011 [0.009, 0.016]; .000
A42: 25-50% | B42: -0.000 [-0.002, 0.001]; .852 | C42: -0.007 [-0.010, -0.005]; .000 | D42: -0.086 [-0.091, -0.076]; .000 | E42: -0.031 [-0.044, -0.027]; .000 | F42: 0.002 [0.001, 0.004]; .027
A43: 25-75% | B43: 0.004 [0.001, 0.005]; .000 | C43: -0.004 [-0.007, 0.001]; .005 | D43: -0.069 [-0.079, 0.000]; .000 | E43: 0.006 [-0.007, 0.014]; .927 | F43: 0.003 [0.001, 0.006]; .000
A44: 25-100% | B44: 0.012 [0.009, 0.016]; .000 | C44: 0.007 [0.007, 0.008]; .000 | D44: -0.098 [-0.100, -0.096]; .000 | E44: 0.043 [0.032, 0.048]; .000 | F44: 0.013 [0.008, 0.015]; .000
A45: 50-75% | B45: 0.003 [0.001, 0.005]; .001 | C45: 0.004 [0.001, 0.007]; .008 | D45: -0.019 [-0.022, 0.071]; .046 | E45: 0.039 [0.027, 0.043]; .000 | F45: 0.001 [-0.001, 0.004]; .161
A46: 50-100% | B46: 0.011 [0.010, 0.015]; .000 | C46: 0.015 [0.011, 0.016]; .000 | D46: -0.022 [-0.022, -0.010]; .000 | E46: 0.069 [0.062, 0.077]; .000 | F46: 0.011 [0.008, 0.014]; .000
A47: 75-100% | B47: 0.007 [0.004, 0.014]; .000 | C47: 0.010 [0.006, 0.014]; .000 | D47: 0.000 [0.000, 0.000]; .000 | E47: 0.036 [0.027, 0.040]; .000 | F47: 0.008 [0.005, 0.011]; .000

Sheet Mitigation Performance
A1: Model | E1: RF | F1: RF | G1: RF | H1: RF | I1: RFRetuned | J1: RFRetuned | K1: RFRetuned | L1: RFRetuned | M1: DT | N1: DT | O1: DT | P1: DT | Q1: GBR | R1: GBR | S1: GBR | T1: GBR | U1: rt | V1: rt | W1: rt | X1: rt
E2: L2 Median | F2: L2 P-Value | G2: L2 Unmitigated Median | H2: L2 Unmitigated P-Value | I2: L2 Median | J2: L2 P-Value | K2: L2 Unmitigated Median | L2: L2 Unmitigated P-Value | M2: L2 Median | N2: L2 P-Value | O2: L2 Unmitigated Median | P2: L2 Unmitigated P-Value | Q2: L2 Median | R2: L2 P-Value | S2: L2 Unmitigated Median | T2: L2 Unmitigated P-Value | U2: L2 Median | V2: L2 P-Value | W2: L2 Unmitigated Median | X2: L2 Unmitigated P-Value
A3: Proportion | B3: circuit_family | C3: n | D3: d
A4: 0 | B4: RB | C4: 3 | D4: 1 | E4: 0.087676755 | F4: 0.00019996001 | G4: 0.16158512 | H4: 0.00019996001 | I4: 0.11395535 | J4: 0.00019996001 | K4: 0.16158512 | L4: 0.00019996001 | M4: 0 | N4: 1 | O4: 0.16158512 | P4: 0.00019996001 | Q4: 0.034091579 | R4: 0.00019996001 | S4: 0.16158512 | T4: 0.00019996001 | U4: 0.038672606 | V4: 0.00019996001 | W4: 0.15583075 | X4: 0.00019996001
A5: 0 | B5: RB | C5: 3 | D5: 3 | E5: 0.077769384 | F5: 0.00019996001 | G5: 0.17378133 | H5: 0.00019996001 | I5: 0.12284272 | J5: 0.00019996001 | K5: 0.17378133 | L5: 0.00019996001 | M5: 0 | N5: 1 | O5: 0.17378133 | P5: 0.00019996001 | Q5: 0.065382835 | R5: 0.00019996001 | S5: 0.17378133 | T5: 0.00019996001 | U5: 0.029818575 | V5: 0.00019996001 | W5: 0.14996882 | X5: 0.00019996001
A6: 0 | B6: RB | C6: 3 | D6: 5 | E6: 0.096693582 | F6: 0.00019996001 | G6: 0.17637735 | H6: 0.00019996001 | I6: 0.12471848 | J6: 0.00019996001 | K6: 0.17637735 | L6: 0.00019996001 | M6: 0 | N6: 1 | O6: 0.17637735 | P6: 0.00019996001 | Q6: 0.057005934 | R6: 0.00019996001 | S6: 0.17637735 | T6: 0.00019996001 | U6: 0.03987379 | V6: 0.00019996001 | W6: 0.14936744 | X6: 0.00019996001
A7: 0 | B7: RB | C7: 3 | D7: 7 | E7: 0.094263476 | F7: 0.00019996001 | G7: 0.17213015 | H7: 0.00019996001 | I7: 0.12030982 | J7: 0.00019996001 | K7: 0.17213015 | L7: 0.00019996001 | M7: 0 | N7: 1 | O7: 0.17213015 | P7: 0.00019996001 | Q7: 0.051115154 | R7: 0.00019996001 | S7: 0.17213015 | T7: 0.00019996001 | U7: 0.067948373 | V7: 0.00019996001 | W7: 0.16354253 | X7: 0.00019996001
A8: 0 | B8: RB | C8: 3 | D8: 9 | E8: 0.10060979 | F8: 0.00019996001 | G8: 0.18066118 | H8: 0.00019996001 | I8: 0.12703825 | J8: 0.00019996001 | K8: 0.18066118 | L8: 0.00019996001 | M8: 0 | N8: 1 | O8: 0.18066118 | P8: 0.00019996001 | Q8: 0.053959996 | R8: 0.00019996001 | S8: 0.18066118 | T8: 0.00019996001 | U8: 0.076257865 | V8: 0.00019996001 | W8: 0.17360585 | X8: 0.00019996001
A9: 0 | B9: RB | C9: 5 | D9: 1 | E9: 0.023248667 | F9: 0.00019996001 | G9: 0.1199051 | H9: 0.00019996001 | I9: 0.038647363 | J9: 0.00019996001 | K9: 0.1199051 | L9: 0.00019996001 | M9: 0 | N9: 1 | O9: 0.1199051 | P9: 0.00019996001 | Q9: 0.077379554 | R9: 0.00019996001 | S9: 0.1199051 | T9: 0.00019996001 | U9: 0.029142139 | V9: 0.00019996001 | W9: 0.11043619 | X9: 0.00019996001
A10: 0 | B10: RB | C10: 5 | D10: 3 | E10: 0.035062769 | F10: 0.00019996001 | G10: 0.13849339 | H10: 0.00019996001 | I10: 0.054527375 | J10: 0.00019996001 | K10: 0.13849339 | L10: 0.00019996001 | M10: 0 | N10: 1 | O10: 0.13849339 | P10: 0.00019996001 | Q10: 0.047163617 | R10: 0.00019996001 | S10: 0.13849339 | T10: 0.00019996001 | U10: 0.037783367 | V10: 0.00019996001 | W10: 0.13620394 | X10: 0.00019996001
A11: 0 | B11: RB | C11: 5 | D11: 5 | E11: 0.064480606 | F11: 0.00019996001 | G11: 0.16218068 | H11: 0.00019996001 | I11: 0.071516037 | J11: 0.00019996001 | K11: 0.16218068 | L11: 0.00019996001 | M11: 0 | N11: 1 | O11: 0.16218068 | P11: 0.00019996001 | Q11: 0.073277223 | R11: 0.00019996001 | S11: 0.16218068 | T11: 0.00019996001 | U11: 0.040294209 | V11: 0.00019996001 | W11: 0.13329315 | X11: 0.00019996001
A12: 0 | B12: RB | C12: 5 | D12: 7 | E12: 0.055182037 | F12: 0.00019996001 | G12: 0.15624495 | H12: 0.00019996001 | I12: 0.076644898 | J12: 0.00019996001 | K12: 0.15624495 | L12: 0.00019996001 | M12: 0 | N12: 1 | O12: 0.15624495 | P12: 0.00019996001 | Q12: 0.058950311 | R12: 0.00019996001 | S12: 0.15624495 | T12: 0.00019996001 | U12: 0.0426035 | V12: 0.00019996001 | W12: 0.14649068 | X12: 0.00019996001
A13: 0 | B13: RB | C13: 5 | D13: 9 | E13: 0.06098565 | F13: 0.00019996001 | G13: 0.16423668 | H13: 0.00019996001 | I13: 0.069891902 | J13: 0.00019996001 | K13: 0.16423668 | L13: 0.00019996001 | M13: 0 | N13: 1 | O13: 0.16423668 | P13: 0.00019996001 | Q13: 0.072188496 | R13: 0.00019996001 | S13: 0.16423668 | T13: 0.00019996001 | U13: 0.044437417 | V13: 0.00019996001 | W13: 0.15337759 | X13: 0.00019996001
A14: 0 | B14: mirror | C14: 3 | D14: 1 | E14: 0.11154503 | F14: 0.00019996001 | G14: 0.17875987 | H14: 0.00019996001 | I14: 0.13878091 | J14: 0.00019996001 | K14: 0.17875987 | L14: 0.00019996001 | M14: 0.12239826 | N14: 0.047790442 | O14: 0.17875987 | P14: 0.00019996001 | Q14: 0.056144325 | R14: 0.00019996001 | S14: 0.17875987 | T14: 0.00019996001 | U14: 0.060821337 | V14: 0.047790442 | W14: 0.14799268 | X14: 0.00019996001
A15: 0 | B15: mirror | C15: 3 | D15: 3 | E15: 0.10955969 | F15: 0.00019996001 | G15: 0.17753045 | H15: 0.00019996001 | I15: 0.1407095 | J15: 0.00019996001 | K15: 0.17753045 | L15: 0.00019996001 | M15: 0 | N15: 1 | O15: 0.17753045 | P15: 0.00019996001 | Q15: 0.062938894 | R15: 0.00019996001 | S15: 0.17753045 | T15: 0.00019996001 | U15: 0.13365502 | V15: 0.00019996001 | W15: 0.20874172 | X15: 0.00019996001
... A103: 1 | B103: mirror | C103: 5 | D103: 9 | E103: 0.13135487 | F103: 0.00019996001 | G103: 0.22261541 | H103: 0.00019996001 | I103: 0.13662102 | J103: 0.00019996001 | K103: 0.22261541 | L103: 0.00019996001 | M103: 0.16099689 | N103: 0.051589682 | O103: 0.22261541 | P103: 0.00019996001 | Q103: 0.081889258 | R103: 0.00019996001 | S103: 0.22261541 | T103: 0.00019996001 | U103: 0.15520107 | V103: 0.00019996001 | W103: 0.24489424 | X103: 0.00019996001

Sheet Mitigation Condensed
A1: Model | C1: RF | D1: RF | E1: RFRetuned | F1: RFRetuned | G1: DT | H1: DT | I1: GBR | J1: GBR | K1: Retest | L1: Retest
C2: L2 Median | D2: L2 P-Value | E2: L2 Median | F2: L2 P-Value | G2: L2 Median | H2: L2 P-Value | I2: L2 Median | J2: L2 P-Value | K2: L2 Median | L2: L2 P-Value
A3: Proportion | B3: Group Value
A4: 0 | B4: RB | C4: 0.0721361 | D4: 0.00019996001 | E4: 0.097443136 | F4: 0.00019996001 | G4: 0 | H4: 1 | I4: 0.067155128 | J4: 0.00019996001 | K4: 0.043098362 | L4: 0.00019996001
A5: 0 | B5: mirror | C5: 0.12015103 | D5: 0.00019996001 | E5: 0.1404459 | F5: 0.00019996001 | G5: 0.18827692 | H5: 0.020195961 | I5: 0.077583373 | J5: 0.00019996001 | K5: 0.12685624 | L5: 0.00019996001
A6: 0 | B6: depth = 1 | C6: 0.086279081 | D6: 0.00019996001 | E6: 0.10959183 | F6: 0.00019996001 | G6: 0 | H6: 1 | I6: 0.057886379 | J6: 0.00019996001 | K6: 0.059521569 | L6: 0.0027994401
A7: 0 | B7: depth = 3 | C7: 0.077769384 | D7: 0.00019996001 | E7: 0.11269502 | F7: 0.00019996001 | G7: 0 | H7: 1 | I7: 0.065382835 | J7: 0.00019996001 | K7: 0.06160974 | L7: 0.017196561
A8: 0 | B8: depth = 5 | C8: 0.1061784 | D8: 0.00019996001 | E8: 0.12312636 | F8: 0.00019996001 | G8: 0.094138462 | H8: 0.81383723 | I8: 0.073881683 | J8: 0.00019996001 | K8: 0.057986049 | L8: 0.070785843
A9: 0 | B9: depth = 7 | C9: 0.11023877 | D9: 0.00019996001 | E9: 0.12599554 | F9: 0.00019996001 | G9: 0 | H9: 1 | I9: 0.070792506 | J9: 0.00019996001 | K9: 0.074530093 | L9: 0.00019996001 | N9: Average
A10: 0 | B10: depth = 9 | C10: 0.10512811 | D10: 0.00019996001 | E10: 0.12999839 | F10: 0.00019996001 | G10: 0 | H10: 1 | I10: 0.070943866 | J10: 0.00019996001 | K10: 0.094941369 | L10: 0.00019996001 | N10: RF | O10: RF | P10: RFRetuned | Q10: RFRetuned | R10: DT | S10: DT | T10: GBR | U10: GBR | V10: Retest | W10: Retest
A11: 0 | B11: length = 3 | C11: 0.10566545 | D11: 0.00019996001 | E11: 0.12913836 | F11: 0.00019996001 | G11: 0 | H11: 1 | I11: 0.057888297 | J11: 0.00019996001 | K11: 0.073633189 | L11: 0.00019996001 | N11: L2 Median | O11: L2 P-Value | P11: L2 Median | Q11: L2 P-Value | R11: L2 Median | S11: L2 P-Value | T11: L2 Median | U11: L2 P-Value | V11: L2 Median | W11: L2 P-Value
A12: 0 | B12: length = 5 | C12: 0.068940489 | D12: 0.00019996001 | E12: 0.086080507 | F12: 0.00019996001 | G12: 0 | H12: 1 | I12: 0.074069344 | J12: 0.00019996001 | K12: 0.057986049 | L12: 0.0081983603 | N12: =MEDIAN(C4:C12) -> 0.10512811 | O12: =MEDIAN(D4:D12) -> 0.00019996001 | P12: =MEDIAN(E4:E12) -> 0.12312636 | Q12: =MEDIAN(F4:F12) -> 0.00019996001 | R12: =MEDIAN(G4:G12) -> 0 | S12: =MEDIAN(H4:H12) -> 1 | T12: =MEDIAN(I4:I12) -> 0.070792506 | U12: =MEDIAN(J4:J12) -> 0.00019996001 | ... W12: =MEDIAN(L4:L12) -> 0.00019996001
A13: 0.25 | B13: RB | C13: 0.063428828 | D13: 0.00019996001 | E13: 0.099462662 | F13: 0.00019996001 | G13: 0.092678098 | H13: 0.00019996001 | I13: 0.042683395 | J13: 0.00019996001 | K13: 0.056815486 | L13: 0.00019996001
A14: 0.25 | B14: mirror | C14: 0.11251426 | D14: 0.00019996001 | E14: 0.13537096 | F14: 0.00019996001 | G14: 0.13637693 | H14: 0.00019996001 | I14: 0.11885482 | J14: 0.00019996001 | K14: 0.13371595 | L14: 0.00019996001
A15: 0.25 | B15: depth = 1 | C15: 0.086915001 | D15: 0.00019996001 | E15: 0.1068105 | F15: 0.00019996001 | G15: 0.085746288 | H15: 0.098180364 | I15: 0.044199697 | J15: 0.0047990402 | K15: 0.073575098 | L15: 0.00019996001
A16: 0.25 | B16: depth = 3 | C16: 0.081665311 | D16: 0.00019996001 | E16: 0.11073313 | F16: 0.00019996001 | G16: 0.10911021 | H16: 0.00019996001 | I16: 0.038258604 | J16: 0.099780044 | K16: 0.087848371 | L16: 0.00019996001
A17: 0.25 | B17: depth = 5 | C17: 0.10255285 | D17: 0.00019996001 | E17: 0.12199605 | F17: 0.00019996001 | G17: 0.10751744 | H17: 0.00019996001 | I17: 0.073481863 | J17: 0.00019996001 | K17: 0.078302342 | L17: 0.00019996001
A18: 0.25 | B18: depth = 7 | C18: 0.10298703 | D18: 0.00019996001 | E18: 0.12462478 | F18: 0.00019996001 | G18: 0.10093613 | H18: 0.00119976 | I18: 0.068194306 | J18: 0.0035992801 | K18: 0.094891803 | L18: 0.00019996001
A19: 0.25 | B19: depth = 9 | C19: 0.10619219 | D19: 0.00019996001 | E19: 0.13141767 | F19: 0.00019996001 | G19: 0.11415011 | H19: 0.00019996001 | I19: 0.074500676 | J19: 0.00019996001 | K19: 0.10791955 | L19: 0.00019996001
A20: 0.25 | B20: length = 3 | C20: 0.10837499 | D20: 0.00019996001 | E20: 0.13075022 | F20: 0.00019996001 | G20: 0.1125833 | H20: 0.00019996001 | I20: 0.069712249 | J20: 0.00019996001 | K20: 0.096716756 | L20: 0.00019996001
A21: 0.25 | B21: length = 5 | C21: 0.062043043 | D21: 0.00019996001 | E21: 0.089516477 | F21: 0.00019996001 | G21: 0.081616481 | H21: 0.00019996001 | I21: 0.045819182 | J21: 0.0023995201 | K21: 0.074254033 | L21: 0.00019996001 | N21: =MEDIAN(C13:C21) -> 0.10255285 | O21: =MEDIAN(D13:D21) -> 0.00019996001 | P21: =MEDIAN(E13:E21) -> 0.12199605 | Q21: =MEDIAN(F13:F21) -> 0.00019996001 | R21: =MEDIAN(G13:G21) -> 0.10751744 | S21: =MEDIAN(H13:H21) -> 0.00019996001 | T21: =MEDIAN(I13:I21) -> 0.068194306 | U21: =MEDIAN(J13:J21) -> 0.00019996001 | ... W21: =MEDIAN(L13:L21) -> 0.00019996001
A22: 0.5 | B22: RB | C22: 0.079767613 | D22: 0.00019996001 | E22: 0.10732509 | F22: 0.00019996001 | G22: 0.022 | H22: 0.00019996001 | I22: 0.021888533 | J22: 0.00019996001 | K22: 0.039084282 | L22: 0.00019996001
A23: 0.5 | B23: mirror | C23: 0.11312282 | D23: 0.00019996001 | E23: 0.12592983 | F23: 0.00019996001 | G23: 0.017041127 | H23: 0.00019996001 | I23: 0.043248071 | J23: 0.00019996001 | K23: 0.12107627 | L23: 0.00019996001
A24: 0.5 | B24: depth = 1 | C24: 0.086351661 | D24: 0.00019996001 | E24: 0.10825689 | F24: 0.00019996001 | G24: 0.020838699 | H24: 0.00019996001 | I24: 0.029104287 | J24: 0.0063987203 | K24: 0.065758948 | L24: 0.00019996001
A25: 0.5 | B25: depth = 3 | C25: 0.08241046 | D25: 0.00019996001 | E25: 0.11047588 | F25: 0.00019996001 | G25: 0.022 | H25: 0.00019996001 | I25: 0.023087656 | J25: 0.00059988002 | K25: 0.069914761 | L25: 0.00019996001
A26: 0.5 | B26: depth = 5 | C26: 0.09890365 | D26: 0.00019996001 | E26: 0.11639148 | F26: 0.00019996001 | G26: 0.022 | H26: 0.00019996001 | I26: 0.034213603 | J26: 0.00099980004 | K26: 0.068243348 | L26: 0.018596281
A27: 0.5 | B27: depth = 7 | C27: 0.10385962 | D27: 0.00019996001 | E27: 0.11986197 | F27: 0.00019996001 | G27: 0.020838699 | H27: 0.00019996001 | I27: 0.030540379 | J27: 0.0077984403 | K27: 0.090736504 | L27: 0.00019996001
A28: 0.5 | B28: depth = 9 | C28: 0.10541969 | D28: 0.00019996001 | E28: 0.12588429 | F28: 0.00019996001 | G28: 0.020838699 | H28: 0.00019996001 | I28: 0.037086257 | J28: 0.00079984003 | K28: 0.1040887 | L28: 0.00019996001
A29: 0.5 | B29: length = 3 | C29: 0.10409952 | D29: 0.00019996001 | E29: 0.12284484 | F29: 0.00019996001 | G29: 0.022 | H29: 0.00019996001 | I29: 0.039388323 | J29: 0.00019996001 | K29: 0.092075456 | L29: 0.00019996001
A30: 0.5 | B30: length = 5 | C30: 0.064997648 | D30: 0.00019996001 | E30: 0.065925702 | F30: 0.00019996001 | G30: 0.022 | H30: 0.00019996001 | I30: 0.027927749 | J30: 0.00019996001 | K30: 0.052120903 | L30: 0.0087982404 | N30: =MEDIAN(C22:C30) -> 0.09890365 | O30: =MEDIAN(D22:D30) -> 0.00019996001 | P30: =MEDIAN(E22:E30) -> 0.11639148 | Q30: =MEDIAN(F22:F30) -> 0.00019996001 | R30: =MEDIAN(G22:G30) -> 0.022 | S30: =MEDIAN(H22:H30) -> 0.00019996001 | T30: =MEDIAN(I22:I30) -> 0.030540379 | U30: =MEDIAN(J22:J30) -> 0.00059988002 | ... W30: =MEDIAN(L22:L30) -> 0.00019996001
A31: 0.75 | B31: RB | C31: 0.08253978 | D31: 0.00019996001 | E31: 0.10361742 | F31: 0.00019996001 | G31: 0 | H31: 1 | I31: 0.05990075 | J31: 0.00019996001 | K31: 0.04071585 | L31: 0.00019996001
A32: 0.75 | B32: mirror | C32: 0.12153589 | D32: 0.00019996001 | E32: 0.131672 | F32: 0.00019996001 | G32: 0.16099689 | H32: 0.00019996001 | I32: 0.086575405 | J32: 0.00019996001 | K32: 0.11976955 | L32: 0.00019996001
A33: 0.75 | B33: depth = 1 | C33: 0.090931288 | D33: 0.00019996001 | E33: 0.10504913 | F33: 0.00019996001 | G33: 0 | H33: 1 | I33: 0.06863119 | J33: 0.00019996001 | K33: 0.063450819 | L33: 0.00019996001
A34: 0.75 | B34: depth = 3 | C34: 0.090092232 | D34: 0.00019996001 | E34: 0.11073362 | F34: 0.00019996001 | G34: 0 | H34: 1 | I34: 0.061828607 | J34: 0.00019996001 | K34: 0.080501705 | L34: 0.00019996001
A35: 0.75 | B35: depth = 5 | C35: 0.10815901 | D35: 0.00019996001 | E35: 0.12499552 | F35: 0.00019996001 | G35: 0.080498447 | H35: 0.81383723 | I35: 0.075857823 | J35: 0.00019996001 | K35: 0.066161064 | L35: 0.018596281
A36: 0.75 | B36: depth = 7 | C36: 0.11118567 | D36: 0.00019996001 | E36: 0.12904904 | F36: 0.00019996001 | G36: 0.16099689 | H36: 0.22215557 | I36: 0.079367435 | J36: 0.00019996001 | K36: 0.092704234 | L36: 0.00019996001
A37: 0.75 | B37: depth = 9 | C37: 0.11123442 | D37: 0.00019996001 | E37: 0.13476473 | F37: 0.00019996001 | G37: 0 | H37: 1 | I37: 0.068311881 | J37: 0.00019996001 | K37: 0.10966683 | L37: 0.00019996001
A38: 0.75 | B38: length = 3 | C38: 0.1074767 | D38: 0.00019996001 | E38: 0.13411819 | F38: 0.00019996001 | G38: 0 | H38: 1 | I38: 0.076038165 | J38: 0.00019996001 | K38: 0.094916974 | L38: 0.00019996001
A39: 0.75 | B39: length = 5 | C39: 0.066136875 | D39: 0.00019996001 | E39: 0.074537102 | F39: 0.00019996001 | G39: 0 | H39: 1 | I39: 0.061945682 | J39: 0.00019996001 | K39: 0.051971512 | L39: 0.13817237 | N39: =MEDIAN(C31:C39) -> 0.1074767 | O39: =MEDIAN(D31:D39) -> 0.00019996001 | P39: =MEDIAN(E31:E39) -> 0.12499552 | Q39: =MEDIAN(F31:F39) -> 0.00019996001 | R39: =MEDIAN(G31:G39) -> 0 | S39: =MEDIAN(H31:H39) -> 1 | T39: =MEDIAN(I31:I39) -> 0.06863119 | U39: =MEDIAN(J31:J39) -> 0.00019996001 | ... W39: =MEDIAN(L31:L39) -> 0.00019996001
A40: 1 | B40: RB | C40: 0.089666039 | D40: 0.00019996001 | E40: 0.10983981 | F40: 0.00019996001 | G40: 0 | H40: 1 | I40: 0.090020815 | J40: 0.00019996001 | K40: 0.041868292 | L40: 0.00019996001
...

Sheet Unmitigated
C1: Baseline | D1: Retest
A2: Proportion | B2: Group Value | C2: L2 Unmitigated Median | D2: L2 Unmitigated Median
A4: 0 | B4: RB | C4: 0.16596302 | D4: 0.1470639
A5: 0 | B5: mirror | C5: 0.19864597 | D5: 0.2107839
A6: 0 | B6: depth = 1 | C6: 0.15674708 | D6: 0.14799268
A7: 0 | B7: depth = 3 | C7: 0.16851941 | D7: 0.16782986
A8: 0 | B8: depth = 5 | C8: 0.18708791 | D8: 0.16204223
A9: 0 | B9: depth = 7 | C9: 0.18556205 | D9: 0.17374841
A10: 0 | B10: depth = 9 | C10: 0.18961654 | D10: 0.18853551
A11: 0 | B11: length = 3 | C11: 0.17936278 | D11: 0.17621822
A12: 0 | B12: length = 5 | C12: 0.16522865 | D12: 0.16030497
A13: 0.25 | B13: RB | C13: 0.16596302 | D13: 0.1470639
A14: 0.25 | B14: mirror | C14: 0.19864597 | D14: 0.2107839
A15: 0.25 | B15: depth = 1 | C15: 0.15674708 | D15: 0.14799268
... A48: 1 | B48: length = 5 | C48: 0.16522865 | D48: 0.16030497

Sheet Mitigation Nice
A1: Model | B1: L2 Median (p)
A2: Proportion | B2: Group Value | C2: RF | D2: RFRetuned | E2: DT | F2: GBR | G2: Retest | H2: Unmitigated Error | I2: Unmitigated Error (retest) | L2: Model | M2: L2 Median (p)
A3: 0 | B3: RB | C3: =TEXT(ROUND('Mitigation Condensed'!C4,3),"0.000") & " (" & TEXT(ROUND('Mitigation Condensed'!D4,3),"0.000") & ")" -> 0.072 (0.000) | D3: =TEXT(ROUND('Mitigation Condensed'!E4,3),"0.000") & " (" & TEXT(ROUND('Mitigation Condensed'!F4,3),"0.000") & ")" -> 0.097 (0.000) | E3: =TEXT(ROUND('Mitigation Condensed'!G4,3),"0.000") & " (" & TEXT(ROUND('Mitigation Condensed'!H4,3),"0.000") & ")" -> 0.000 (1.000) | F3: =TEXT(ROUND('Mitigation Condensed'!I4,3),"0.000") & " (" & TEXT(ROUND('Mitigation Condensed'!J4,3),"0.000") & ")" -> 0.067 (0.000) | G3: =TEXT(ROUND('Mitigation Condensed'!K4,3),"0.000") & " (" & TEXT(ROUND('Mitigation Condensed'!L4,3),"0.000") & ")" -> 0.043 (0.000) | H3: =Unmitigated!C4 -> 0.16596302 | I3: =Unmitigated!D4 -> 0.1470639 | L3: Factor | M3: Family | N3: RF | O3: RFRetuned | P3: DT | Q3: GBR | R3: Retest | S3: Unmit. | T3: Unmit. (retest)
A4: 0 | B4: mirror | C4: =TEXT(ROUND('Mitigation Condensed'!C5,3),"0.000") & " (" & TEXT(ROUND('Mitigation Condensed'!D5,3),"0.000") & ")" -> 0.120 (0.000) | D4: =TEXT(ROUND('Mitigation Condensed'!E5,3),"0.000") & " (" & TEXT(ROUND('Mitigation Condensed'!F5,3),"0.000") & ")" -> 0.140 (0.000) | E4: =TEXT(ROUND('Mitigation Condensed'!G5,3),"0.000") & " (" & TEXT(ROUND('Mitigation Condensed'!H5,3),"0.000") & ")" -> 0.188 (0.020) | F4: =TEXT(ROUND('Mitigation Condensed'!I5,3),"0.000") & " (" & TEXT(ROUND('Mitigation Condensed'!J5,3),"0.000") & ")" -> 0.078 (0.000) | G4: =TEXT(ROUND('Mitigation Condensed'!K5,3),"0.000") & " (" & TEXT(ROUND('Mitigation Condensed'!L5,3),"0.000") & ")" -> 0.127 (0.000) | H4: =Unmitigated!C5 -> 0.19864597 | I4: =Unmitigated!D5 -> 0.2107839 | L4: 0 | M4: RB | N4: 0.072 (0.000) | O4: 0.097 (0.000) | P4: 0.000 (1.000) | Q4: 0.067 (0.000) | R4: 0.043 (0.000) | S4: 0.16596302 | T4: 0.1470639
A5: 0 | B5: depth = 1 | C5: =TEXT(ROUND('Mitigation Condensed'!C6,3),"0.000") & " (" & TEXT(ROUND('Mitigation Condensed'!D6,3),"0.000") & ")" -> 0.086 (0.000) | D5: =TEXT(ROUND('Mitigation Condensed'!E6,3),"0.000") & " (" & TEXT(ROUND('Mitigation Condensed'!F6,3),"0.000") & ")" -> 0.110 (0.000) | E5: =TEXT(ROUND('Mitigation Condensed'!G6,3),"0.000") & " (" & TEXT(ROUND('Mitigation Condensed'!H6,3),"0.000") & ")" -> 0.000 (1.000) | F5: =TEXT(ROUND('Mitigation Condensed'!I6,3),"0.000") & " (" & TEXT(ROUND('Mitigation Condensed'!J6,3),"0.000") & ")" -> 0.058 (0.000) | G5: =TEXT(ROUND('Mitigation Condensed'!K6,3),"0.000") & " (" & TEXT(ROUND('Mitigation Condensed'!L6,3),"0.000") & ")" -> 0.060 (0.003) | H5: =Unmitigated!C6 -> 0.15674708 | I5: =Unmitigated!D6 -> 0.14799268 | L5: 0.25 | M5: RB | N5: 0.063 (0.000) | O5: 0.099 (0.000) | P5: 0.093 (0.000) | Q5: 0.043 (0.000) | R5: 0.057 (0.000) | S5: 0.16596302 | T5: 0.1470639
A6: 0 | B6: depth = 3 | C6: =TEXT(ROUND('Mitigation Condensed'!C7,3),"0.000") & " (" & TEXT(ROUND('Mitigation Condensed'!D7,3),"0.000") & ")" -> 0.078 (0.000) | D6: =TEXT(ROUND('Mitigation Condensed'!E7,3),"0.000") & " (" & TEXT(ROUND('Mitigation Condensed'!F7,3),"0.000") & ")" -> 0.113 (0.000) | E6: =TEXT(ROUND('Mitigation Condensed'!G7,3),"0.000") & " (" & TEXT(ROUND('Mitigation Condensed'!H7,3),"0.000") & ")" -> 0.000 (1.000) | F6: =TEXT(ROUND('Mitigation Condensed'!I7,3),"0.000") & " (" & TEXT(ROUND('Mitigation Condensed'!J7,3),"0.000") & ")" -> 0.065 (0.000) | G6: =TEXT(ROUND('Mitigation Condensed'!K7,3),"0.000") & " (" & TEXT(ROUND('Mitigation Condensed'!L7,3),"0.000") & ")" -> 0.062 (0.017) | H6: =Unmitigated!C7 -> 0.16851941 | I6: =Unmitigated!D7 -> 0.16782986 | L6: 0.5 | M6: RB | N6: 0.080 (0.000) | O6: 0.107 (0.000) | P6: 0.022 (0.000) | Q6: 0.022 (0.000) | R6: 0.039 (0.000) | S6: 0.16596302 | T6: 0.1470639
A7: 0 | B7: depth = 5 | C7: =TEXT(ROUND('Mitigation Condensed'!C8,3),"0.000") & " (" & TEXT(ROUND('Mitigation Condensed'!D8,3),"0.000") & ")" -> 0.106 (0.000) | D7: =TEXT(ROUND('Mitigation Condensed'!E8,3),"0.000") & " (" & TEXT(ROUND('Mitigation Condensed'!F8,3),"0.000") & ")" -> 0.123 (0.000) | E7: =TEXT(ROUND('Mitigation Condensed'!G8,3),"0.000") & " (" & TEXT(ROUND('Mitigation Condensed'!H8,3),"0.000") & ")" -> 0.094 (0.814) | F7: =TEXT(ROUND('Mitigation Condensed'!I8,3),"0.000") & " (" & TEXT(ROUND('Mitigation Condensed'!J8,3),"0.000") & ")" -> 0.074 (0.000) | G7: =TEXT(ROUND('Mitigation Condensed'!K8,3),"0.000") & " (" & TEXT(ROUND('Mitigation Condensed'!L8,3),"0.000") & ")" -> 0.058 (0.071) | H7: =Unmitigated!C8 -> 0.18708791 | I7: =Unmitigated!D8 -> 0.16204223 | L7: 0.75 | M7: RB | N7: 0.083 (0.000) | O7: 0.104 (0.000) | P7: 0.000 (1.000) | Q7: 0.060 (0.000) | R7: 0.041 (0.000) | S7: 0.16596302 | T7: 0.1470639
A8: 0 | B8: depth = 7 | C8: =TEXT(ROUND('Mitigation Condensed'!C9,3),"0.000") & " (" & TEXT(ROUND('Mitigation Condensed'!D9,3),"0.000") & ")" -> 0.110 (0.000) | D8: =TEXT(ROUND('Mitigation Condensed'!E9,3),"0.000") & " (" & TEXT(ROUND('Mitigation Condensed'!F9,3),"0.000") & ")" -> 0.126 (0.000) | E8: =TEXT(ROUND('Mitigation Condensed'!G9,3),"0.000") & " (" & TEXT(ROUND('Mitigation Condensed'!H9,3),"0.000") & ")" -> 0.000 (1.000) | F8: =TEXT(ROUND('Mitigation Condensed'!I9,3),"0.000") & " (" & TEXT(ROUND('Mitigation Condensed'!J9,3),"0.000") & ")" -> 0.071 (0.000) | G8: =TEXT(ROUND('Mitigation Condensed'!K9,3),"0.000") & " (" & TEXT(ROUND('Mitigation Condensed'!L9,3),"0.000") & ")" -> 0.075 (0.000) | H8: =Unmitigated!C9 -> 0.18556205 | I8: =Unmitigated!D9 -> 0.17374841 | L8: 1 | M8: RB | N8: 0.090 (0.000) | O8: 0.110 (0.000) | P8: 0.000 (1.000) | Q8: 0.090 (0.000) | R8: 0.042 (0.000) | S8: 0.16596302 | T8: 0.1470639
A9: 0 | B9: depth = 9 | C9: =TEXT(ROUND('Mitigation Condensed'!C10,3),"0.000") & " (" & TEXT(ROUND('Mitigation Condensed'!D10,3),"0.000") & ")" -> 0.105 (0.000) | D9: =TEXT(ROUND('Mitigation Condensed'!E10,3),"0.000") & " (" & TEXT(ROUND('Mitigation Condensed'!F10,3),"0.000") & ")" -> 0.130 (0.000) | E9: =TEXT(ROUND('Mitigation Condensed'!G10,3),"0.000") & " (" & TEXT(ROUND('Mitigation Condensed'!H10,3),"0.000") & ")" -> 0.000 (1.000) | F9: =TEXT(ROUND('Mitigation Condensed'!I10,3),"0.000") & " (" & TEXT(ROUND('Mitigation Condensed'!J10,3),"0.000") & ")" -> 0.071 (0.000) | G9: =TEXT(ROUND('Mitigation Condensed'!K10,3),"0.000") & " (" & TEXT(ROUND('Mitigation Condensed'!L10,3),"0.000") & ")" -> 0.095 (0.000) | H9: =Unmitigated!C10 -> 0.18961654 | I9: =Unmitigated!D10 -> 0.18853551 | L9: 0 | M9: mirror | N9: 0.120 (0.000) | O9: 0.140 (0.000) | P9: 0.188 (0.020) | Q9: 0.078 (0.000) | R9: 0.127 (0.000) | S9: 0.19864597 | T9: 0.2107839
A10: 0 | B10: length = 3 | C10: =TEXT(ROUND('Mitigation Condensed'!C11,3),"0.000") & " (" & TEXT(ROUND('Mitigation Condensed'!D11,3),"0.000") & ")" -> 0.106 (0.000) | D10: =TEXT(ROUND('Mitigation Condensed'!E11,3),"0.000") & " (" & TEXT(ROUND('Mitigation Condensed'!F11,3),"0.000") & ")" -> 0.129 (0.000) | E10: =TEXT(ROUND('Mitigation Condensed'!G11,3),"0.000") & " (" & TEXT(ROUND('Mitigation Condensed'!H11,3),"0.000") & ")" -> 0.000 (1.000) | F10: =TEXT(ROUND('Mitigation Condensed'!I11,3),"0.000") & " (" & TEXT(ROUND('Mitigation Condensed'!J11,3),"0.000") & ")" -> 0.058 (0.000) | G10: =TEXT(ROUND('Mitigation Condensed'!K11,3),"0.000") & " (" & TEXT(ROUND('Mitigation Condensed'!L11,3),"0.000") & ")" -> 0.074 (0.000) | H10: =Unmitigated!C11 -> 0.17936278 | I10: =Unmitigated!D11 -> 0.17621822 | L10: 0.25 | M10: mirror | N10: 0.113 (0.000) | O10: 0.135 (0.000) | P10: 0.136 (0.000) | Q10: 0.119 (0.000) | R10: 0.134 (0.000) | S10: 0.19864597 | T10: 0.2107839
A11: 0 | B11: length = 5 | C11: =TEXT(ROUND('Mitigation Condensed'!C12,3),"0.000") & " (" & TEXT(ROUND('Mitigation Condensed'!D12,3),"0.000") & ")" -> 0.069 (0.000) | D11: =TEXT(ROUND('Mitigation Condensed'!E12,3),"0.000") & " (" & TEXT(ROUND('Mitigation Condensed'!F12,3),"0.000") & ")" -> 0.086 (0.000) | E11: =TEXT(ROUND('Mitigation Condensed'!G12,3),"0.000") & " (" & TEXT(ROUND('Mitigation Condensed'!H12,3),"0.000") & ")" -> 0.000 (1.000) | F11: =TEXT(ROUND('Mitigation Condensed'!I12,3),"0.000") & " (" & TEXT(ROUND('Mitigation Condensed'!J12,3),"0.000") & ")" -> 0.074 (0.000) | G11: =TEXT(ROUND('Mitigation Condensed'!K12,3),"0.000") & " (" & TEXT(ROUND('Mitigation Condensed'!L12,3),"0.000") & ")" -> 0.058 (0.008) | H11: =Unmitigated!C12 -> 0.16522865 | I11: =Unmitigated!D12 -> 0.16030497 | L11: 0.5 | M11: mirror | N11: 0.113 (0.000) | O11: 0.126 (0.000) | P11: 0.017 (0.000) | Q11: 0.043 (0.000) | R11: 0.121 (0.000) | S11: 0.19864597 | T11: 0.2107839
A12: 0.25 | B12: RB | C12: =TEXT(ROUND('Mitigation Condensed'!C13,3),"0.000") & " (" & TEXT(ROUND('Mitigation Condensed'!D13,3),"0.000") & ")" -> 0.063 (0.000) | D12: =TEXT(ROUND('Mitigation Condensed'!E13,3),"0.000") & " (" & TEXT(ROUND('Mitigation Condensed'!F13,3),"0.000") & ")" -> 0.099 (0.000) | E12: =TEXT(ROUND('Mitigation Condensed'!G13,3),"0.000") & " (" & TEXT(ROUND('Mitigation Condensed'!H13,3),"0.000") & ")" -> 0.093 (0.000) | F12: =TEXT(ROUND('Mitigation Condensed'!I13,3),"0.000") & " (" & TEXT(ROUND('Mitigation Condensed'!J13,3),"0.000") & ")" -> 0.043 (0.000) | G12: =TEXT(ROUND('Mitigation Condensed'!K13,3),"0.000") & " (" & TEXT(ROUND('Mitigation Condensed'!L13,3),"0.000") & ")" -> 0.057 (0.000) | H12: =Unmitigated!C13 -> 0.16596302 | I12: =Unmitigated!D13 -> 0.1470639 | L12: 0.75 | M12: mirror | N12: 0.122 (0.000) | O12: 0.132 (0.000) | P12: 0.161 (0.000) | Q12: 0.087 (0.000) | R12: 0.120 (0.000) | S12: 0.19864597 | T12: 0.2107839
A13: 0.25 | B13: mirror | C13: =TEXT(ROUND('Mitigation Condensed'!C14,3),"0.000") & " (" & TEXT(ROUND('Mitigation Condensed'!D14,3),"0.000") & ")" -> 0.113 (0.000) | D13: =TEXT(ROUND('Mitigation Condensed'!E14,3),"0.000") & " (" & TEXT(ROUND('Mitigation Condensed'!F14,3),"0.000") & ")" -> 0.135 (0.000) | E13: =TEXT(ROUND('Mitigation Condensed'!G14,3),"0.000") & " (" & TEXT(ROUND('Mitigation Condensed'!H14,3),"0.000") & ")" -> 0.136 (0.000) | F13: =TEXT(ROUND('Mitigation Condensed'!I14,3),"0.000") & " (" & TEXT(ROUND('Mitigation Condensed'!J14,3),"0.000") & ")" -> 0.119 (0.000) | G13: =TEXT(ROUND('Mitigation Condensed'!K14,3),"0.000") & " (" & TEXT(ROUND('Mitigation Condensed'!L14,3),"0.000") & ")" -> 0.134 (0.000) | H13: =Unmitigated!C14 -> 0.19864597 | I13: =Unmitigated!D14 -> 0.2107839 | L13: 1 | M13: mirror | N13: 0.131 (0.000) | O13: 0.145 (0.000) | P13: 0.010 (0.000) | Q13: 0.115 (0.000) | R13: 0.135 (0.000) | S13: 0.19864597 | T13: 0.2107839
A14: 0.25 | B14: depth = 1 | C14: =TEXT(ROUND('Mitigation Condensed'!C15,3),"0.000") & " (" & TEXT(ROUND('Mitigation Condensed'!D15,3),"0.000") & ")" -> 0.087 (0.000) | D14: =TEXT(ROUND('Mitigation Condensed'!E15,3),"0.000") & " (" & TEXT(ROUND('Mitigation Condensed'!F15,3),"0.000") & ")" -> 0.107 (0.000) | E14: =TEXT(ROUND('Mitigation Condensed'!G15,3),"0.000") & " (" & TEXT(ROUND('Mitigation Condensed'!H15,3),"0.000") & ")" -> 0.086 (0.098) | F14: =TEXT(ROUND('Mitigation Condensed'!I15,3),"0.000") & " (" & TEXT(ROUND('Mitigation Condensed'!J15,3),"0.000") & ")" -> 0.044 (0.005) | G14: =TEXT(ROUND('Mitigation Condensed'!K15,3),"0.000") & " (" & TEXT(ROUND('Mitigation Condensed'!L15,3),"0.000") & ")" -> 0.074 (0.000) | H14: =Unmitigated!C15 -> 0.15674708 | I14: =Unmitigated!D15 -> 0.14799268
A15: 0.25 | B15: depth = 3 | C15: =TEXT(ROUND('Mitigation Condensed'!C16,3),"0.000") & " (" & TEXT(ROUND('Mitigation Condensed'!D16,3),"0.000") & ")" -> 0.082 (0.000) | D15: =TEXT(ROUND('Mitigation Condensed'!E16,3),"0.000") & " (" & TEXT(ROUND('Mitigation Condensed'!F16,3),"0.000") & ")" -> 0.111 (0.000) | E15: =TEXT(ROUND('Mitigation Condensed'!G16,3),"0.000") & " (" & TEXT(ROUND('Mitigation Condensed'!H16,3),"0.000") & ")" -> 0.109 (0.000) | F15: =TEXT(ROUND('Mitigation Condensed'!I16,3),"0.000") & " (" & TEXT(ROUND('Mitigation Condensed'!J16,3),"0.000") & ")" -> 0.038 (0.100) | G15: =TEXT(ROUND('Mitigation Condensed'!K16,3),"0.000") & " (" & TEXT(ROUND('Mitigation Condensed'!L16,3),"0.000") & ")" -> 0.088 (0.000) | H15: =Unmitigated!C16 -> 0.16851941 | I15: =Unmitigated!D16 -> 0.16782986 | L15: Model | M15: L2 Median (p)
A16: 0.25 | B16: depth = 5 | C16: =TEXT(ROUND('Mitigation Condensed'!C17,3),"0.000") & " (" & TEXT(ROUND('Mitigation Condensed'!D17,3),"0.000") & ")" -> 0.103 (0.000) | D16: =TEXT(ROUND('Mitigation Condensed'!E17,3),"0.000") & " (" & TEXT(ROUND('Mitigation Condensed'!F17,3),"0.000") & ")" -> 0.122 (0.000) | E16: =TEXT(ROUND('Mitigation Condensed'!G17,3),"0.000") & " (" & TEXT(ROUND('Mitigation Condensed'!H17,3),"0.000") & ")" -> 0.108 (0.000) | F16: =TEXT(ROUND('Mitigation Condensed'!I17,3),"0.000") & " (" & TEXT(ROUND('Mitigation Condensed'!J17,3),"0.000") & ")" -> 0.073 (0.000) | G16: =TEXT(ROUND('Mitigation Condensed'!K17,3),"0.000") & " (" & TEXT(ROUND('Mitigation Condensed'!L17,3),"0.000") & ")" -> 0.078 (0.000) | H16: =Unmitigated!C17 -> 0.18708791 | I16: =Unmitigated!D17 -> 0.16204223 | L16: Proportion | M16: Group Value | N16: RF | O16: RFRetuned | P16: DT | Q16: GBR | R16: Retest | S16: Unmitigated Error | T16: Unmitigated Error (retest)
A17: 0.25 | B17: depth = 7 | C17: =TEXT(ROUND('Mitigation Condensed'!C18,3),"0.000") & " (" & TEXT(ROUND('Mitigation Condensed'!D18,3),"0.000") & ")" -> 0.103 (0.000) | D17: =TEXT(ROUND('Mitigation Condensed'!E18,3),"0.000") & " (" & TEXT(ROUND('Mitigation Condensed'!F18,3),"0.000") & ")" -> 0.125 (0.000) | E17: =TEXT(ROUND('Mitigation Condensed'!G18,3),"0.000") & " (" & TEXT(ROUND('Mitigation Condensed'!H18,3),"0.000") & ")" -> 0.101 (0.001) | F17: =TEXT(ROUND('Mitigation Condensed'!I18,3),"0.000") & " (" & TEXT(ROUND('Mitigation Condensed'!J18,3),"0.000") & ")" -> 0.068 (0.004) | G17: =TEXT(ROUND('Mitigation Condensed'!K18,3),"0.000") & " (" & TEXT(ROUND('Mitigation Condensed'!L18,3),"0.000") & ")" -> 0.095 (0.000) | H17: =Unmitigated!C18 -> 0.18556205 | I17: =Unmitigated!D18 -> 0.17374841 | L17: 0 | M17: depth = 1 | N17: 0.086 (0.000) | O17: 0.110 (0.000) | P17: 0.000 (1.000) | Q17: 0.058 (0.000) | R17: 0.060 (0.003) | S17: 0.15674708 | T17: 0.14799268
A18: 0.25 | B18: depth = 9 | C18: =TEXT(ROUND('Mitigation Condensed'!C19,3),"0.000") & " (" & TEXT(ROUND('Mitigation Condensed'!D19,3),"0.000") & ")" -> 0.106 (0.000) | D18: =TEXT(ROUND('Mitigation Condensed'!E19,3),"0.000") & " (" & TEXT(ROUND('Mitigation Condensed'!F19,3),"0.000") & ")" -> 0.131 (0.000) | E18: =TEXT(ROUND('Mitigation Condensed'!G19,3),"0.000") & " (" & TEXT(ROUND('Mitigation Condensed'!H19,3),"0.000") & ")" -> 0.114 (0.000) | F18: =TEXT(ROUND('Mitigation Condensed'!I19,3),"0.000") & " (" & TEXT(ROUND('Mitigation Condensed'!J19,3),"0.000") & ")" -> 0.075 (0.000) | G18: =TEXT(ROUND('Mitigation Condensed'!K19,3),"0.000") & " (" & TEXT(ROUND('Mitigation Condensed'!L19,3),"0.000") & ")" -> 0.108 (0.000) | H18: =Unmitigated!C19 -> 0.18961654 | I18: =Unmitigated!D19 -> 0.18853551 | L18: 0.25 | M18: depth = 1 | N18: 0.087 (0.000) | O18: 0.107 (0.000) | P18: 0.086 (0.098) | Q18: 0.044 (0.005) | R18: 0.074 (0.000) | S18: 0.15674708 | T18: 0.14799268
A19: 0.25 | B19: length = 3 | C19: =TEXT(ROUND('Mitigation Condensed'!C20,3),"0.000") & " (" & TEXT(ROUND('Mitigation Condensed'!D20,3),"0.000") & ")" -> 0.108 (0.000) | D19: =TEXT(ROUND('Mitigation Condensed'!E20,3),"0.000") & " (" & TEXT(ROUND('Mitigation Condensed'!F20,3),"0.000") & ")" -> 0.131 (0.000) | E19: =TEXT(ROUND('Mitigation Condensed'!G20,3),"0.000") & " (" & TEXT(ROUND('Mitigation Condensed'!H20,3),"0.000") & ")" -> 0.113 (0.000) | F19: =TEXT(ROUND('Mitigation Condensed'!I20,3),"0.000") & " (" & TEXT(ROUND('Mitigation Condensed'!J20,3),"0.000") & ")" -> 0.070 (0.000) | G19: =TEXT(ROUND('Mitigation Condensed'!K20,3),"0.000") & " (" & TEXT(ROUND('Mitigation Condensed'!L20,3),"0.000") & ")" -> 0.097 (0.000) | H19: =Unmitigated!C20 -> 0.17936278 | I19: =Unmitigated!D20 -> 0.17621822 | L19: 0.5 | M19: depth = 1 | N19: 0.086 (0.000) | O19: 0.108 (0.000) | P19: 0.021 (0.000) | Q19: 0.029 (0.006) | R19: 0.066 (0.000) | S19: 0.15674708 | T19: 0.14799268
A20: 0.25 | B20: length = 5 | C20: =TEXT(ROUND('Mitigation Condensed'!C21,3),"0.000") & " (" & TEXT(ROUND('Mitigation Condensed'!D21,3),"0.000") & ")" -> 0.062 (0.000) | D20: =TEXT(ROUND('Mitigation Condensed'!E21,3),"0.000") & " (" & TEXT(ROUND('Mitigation Condensed'!F21,3),"0.000") & ")" -> 0.090 (0.000) | E20: =TEXT(ROUND('Mitigation Condensed'!G21,3),"0.000") & " (" & TEXT(ROUND('Mitigation Condensed'!H21,3),"0.000") & ")" -> 0.082 (0.000) | F20: =TEXT(ROUND('Mitigation Condensed'!I21,3),"0.000") & " (" & TEXT(ROUND('Mitigation Condensed'!J21,3),"0.000") & ")" -> 0.046 (0.002) | G20: =TEXT(ROUND('Mitigation Condensed'!K21,3),"0.000") & " (" & TEXT(ROUND('Mitigation Condensed'!L21,3),"0.000") & ")" -> 0.074 (0.000) | H20: =Unmitigated!C21 -> 0.16522865 | I20: =Unmitigated!D21 -> 0.16030497 | L20: 0.75 | M20: depth = 1 | N20: 0.091 (0.000) | O20: 0.105 (0.000) | P20: 0.000 (1.000) | Q20: 0.069 (0.000) | R20: 0.063 (0.000) | S20: 0.15674708 | T20: 0.14799268
A21: 0.5 | B21: RB | C21: =TEXT(ROUND('Mitigation Condensed'!C22,3),"0.000") & " (" & TEXT(ROUND('Mitigation Condensed'!D22,3),"0.000") & ")" -> 0.080 (0.000) | D21: =TEXT(ROUND('Mitigation Condensed'!E22,3),"0.000") & " (" & TEXT(ROUND('Mitigation Condensed'!F22,3),"0.000") & ")" -> 0.107 (0.000) | E21: =TEXT(ROUND('Mitigation Condensed'!G22,3),"0.000") & " (" & TEXT(ROUND('Mitigation Condensed'!H22,3),"0.000") & ")" -> 0.022 (0.000) | F21: =TEXT(ROUND('Mitigation Condensed'!I22,3),"0.000") & " (" & TEXT(ROUND('Mitigation Condensed'!J22,3),"0.000") & ")" -> 0.022 (0.000) | G21: =TEXT(ROUND('Mitigation Condensed'!K22,3),"0.000") & " (" & TEXT(ROUND('Mitigation Condensed'!L22,3),"0.000") & ")" -> 0.039 (0.000) | H21: =Unmitigated!C22 -> 0.16596302 | I21: =Unmitigated!D22 -> 0.1470639 | L21: 1 | M21: depth = 1 | N21: 0.085 (0.000) | O21: 0.104 (0.000) | P21: 0.000 (1.000) | Q21: 0.087 (0.000) | R21: 0.076 (0.000) | S21: 0.15674708 | T21: 0.14799268
A22: 0.5 | B22: mirror | C22: =TEXT(ROUND('Mitigation Condensed'!C23,3),"0.000") & " (" & TEXT(ROUND('Mitigation Condensed'!D23,3),"0.000") & ")" -> 0.113 (0.000) | D22: =TEXT(ROUND('Mitigation Condensed'!E23,3),"0.000") & " (" & TEXT(ROUND('Mitigation Condensed'!F23,3),"0.000") & ")" -> 0.126 (0.000) | E22: =TEXT(ROUND('Mitigation Condensed'!G23,3),"0.000") & " (" & TEXT(ROUND('Mitigation Condensed'!H23,3),"0.000") & ")" -> 0.017 (0.000) | F22: =TEXT(ROUND('Mitigation Condensed'!I23,3),"0.000") & " (" & TEXT(ROUND('Mitigation Condensed'!J23,3),"0.000") & ")" -> 0.043 (0.000) | G22: =TEXT(ROUND('Mitigation Condensed'!K23,3),"0.000") & " (" & TEXT(ROUND('Mitigation Condensed'!L23,3),"0.000") & ")" -> 0.121 (0.000) | H22: =Unmitigated!C23 -> 0.19864597 | I22: =Unmitigated!D23 -> 0.2107839 | L22: 0 | M22: depth = 3 | N22: 0.078 (0.000) | O22: 0.113 (0.000) | P22: 0.000 (1.000) | Q22: 0.065 (0.000) | R22: 0.062 (0.017) | S22: 0.16851941 | T22: 0.16782986
A23: 0.5 | B23: depth = 1 | C23: =TEXT(ROUND('Mitigation Condensed'!C24,3),"0.000") & " (" & TEXT(ROUND('Mitigation Condensed'!D24,3),"0.000") & ")" -> 0.086 (0.000) | D23: =TEXT(ROUND('Mitigation Condensed'!E24,3),"0.000") & " (" & TEXT(ROUND('Mitigation Condensed'!F24,3),"0.000") & ")" -> 0.108 (0.000) | E23: =TEXT(ROUND('Mitigation Condensed'!G24,3),"0.000") & " (" & TEXT(ROUND('Mitigation Condensed'!H24,3),"0.000") & ")" -> 0.021 (0.000) | F23: =TEXT(ROUND('Mitigation Condensed'!I24,3),"0.000") & " (" & TEXT(ROUND('Mitigation Condensed'!J24,3),"0.000") & ")" -> 0.029 (0.006) | G23: =TEXT(ROUND('Mitigation Condensed'!K24,3),"0.000") & " (" & TEXT(ROUND('Mitigation Condensed'!L24,3),"0.000") & ")" -> 0.066 (0.000) | H23: =Unmitigated!C24 -> 0.15674708 | I23: =Unmitigated!D24 -> 0.14799268 | L23: 0.25 | M23: depth = 3 | N23: 0.082 (0.000) | O23: 0.111 (0.000) | P23: 0.109 (0.000) | Q23: 0.038 (0.100) | R23: 0.088 (0.000) | S23: 0.16851941 | T23: 0.16782986
A24: 0.5 | B24: depth = 3 | C24: =TEXT(ROUND('Mitigation Condensed'!C25,3),"0.000") & " (" & TEXT(ROUND('Mitigation Condensed'!D25,3),"0.000") & ")" -> 0.082 (0.000) | D24: =TEXT(ROUND('Mitigation Condensed'!E25,3),"0.000") & " (" & TEXT(ROUND('Mitigation Condensed'!F25,3),"0.000") & ")" -> 0.110 (0.000) | E24: =TEXT(ROUND('Mitigation Condensed'!G25,3),"0.000") & " (" & TEXT(ROUND('Mitigation Condensed'!H25,3),"0.000") & ")" -> 0.022 (0.000) | F24: =TEXT(ROUND('Mitigation Condensed'!I25,3),"0.000") & " (" & TEXT(ROUND('Mitigation Condensed'!J25,3),"0.000") & ")" -> 0.023 (0.001) | G24: =TEXT(ROUND('Mitigation Condensed'!K25,3),"0.000") & " (" & TEXT(ROUND('Mitigation Condensed'!L25,3),"0.000") & ")" -> 0.070 (0.000) | H24: =Unmitigated!C25 -> 0.16851941 | I24: =Unmitigated!D25 -> 0.16782986 | L24: 0.5 | M24: depth = 3 | N24: 0.082 (0.000) | O24: 0.110 (0.000) | P24: 0.022 (0.000) | Q24: 0.023 (0.001) | R24: 0.070 (0.000) | S24: 0.16851941 | T24: 0.16782986
A25: 0.5 | B25: depth = 5 | C25: =TEXT(ROUND('Mitigation Condensed'!C26,3),"0.000") & " (" & TEXT(ROUND('Mitigation Condensed'!D26,3),"0.000") & ")" -> 0.099 (0.000) | D25: =TEXT(ROUND('Mitigation Condensed'!E26,3),"0.000") & " (" & TEXT(ROUND('Mitigation Condensed'!F26,3),"0.000") & ")" -> 0.116 (0.000) | E25: =TEXT(ROUND('Mitigation Condensed'!G26,3),"0.000") & " (" & TEXT(ROUND('Mitigation Condensed'!H26,3),"0.000") & ")" -> 0.022 (0.000) | F25: =TEXT(ROUND('Mitigation Condensed'!I26,3),"0.000") & " (" & TEXT(ROUND('Mitigation Condensed'!J26,3),"0.000") & ")" -> 0.034 (0.001) | G25: =TEXT(ROUND('Mitigation Condensed'!K26,3),"0.000") & " (" & TEXT(ROUND('Mitigation Condensed'!L26,3),"0.000") & ")" -> 0.068 (0.019) | H25: =Unmitigated!C26 -> 0.18708791 | I25: =Unmitigated!D26 -> 0.16204223 | L25: 0.75 | M25: depth = 3 | N25: 0.090 (0.000) | O25: 0.111 (0.000) | P25: 0.000 (1.000) | Q25: 0.062 (0.000) | R25: 0.081 (0.000) | S25: 0.16851941 | T25: 0.16782986
A26: 0.5 | B26: depth = 7 | C26: =TEXT(ROUND('Mitigation Condensed'!C27,3),"0.000") & " (" & TEXT(ROUND('Mitigation Condensed'!D27,3),"0.000") & ")" -> 0.104 (0.000) | D26: =TEXT(ROUND('Mitigation Condensed'!E27,3),"0.000") & " (" & TEXT(ROUND('Mitigation Condensed'!F27,3),"0.000") & ")" -> 0.120 (0.000) | E26: =TEXT(ROUND('Mitigation Condensed'!G27,3),"0.000") & " (" & TEXT(ROUND('Mitigation Condensed'!H27,3),"0.000") & ")" -> 0.021 (0.000) | F26: =TEXT(ROUND('Mitigation Condensed'!I27,3),"0.000") & " (" & TEXT(ROUND('Mitigation Condensed'!J27,3),"0.000") & ")" -> 0.031 (0.008) | G26: =TEXT(ROUND('Mitigation Condensed'!K27,3),"0.000") & " (" & TEXT(ROUND('Mitigation Condensed'!L27,3),"0.000") & ")" -> 0.091 (0.000) | H26: =Unmitigated!C27 -> 0.18556205 | I26: =Unmitigated!D27 -> 0.17374841 | L26: 1 | M26: depth = 3 | N26: 0.099 (0.000) | O26: 0.114 (0.000) | P26: 0.000 (1.000) | Q26: 0.090 (0.000) | R26: 0.077 (0.000) | S26: 0.16851941 | T26: 0.16782986
A27: 0.5 | B27: depth = 9 | C27: =TEXT(ROUND('Mitigation Condensed'!C28,3),"0.000") & " (" & TEXT(ROUND('Mitigation Condensed'!D28,3),"0.000") & ")" -> 0.105 (0.000) | D27: =TEXT(ROUND('Mitigation Condensed'!E28,3),"0.000") & " (" & TEXT(ROUND('Mitigation Condensed'!F28,3),"0.000") & ")" -> 0.126 (0.000) | E27: =TEXT(ROUND('Mitigation Condensed'!G28,3),"0.000") & " (" & TEXT(ROUND('Mitigation Condensed'!H28,3),"0.000") & ")" -> 0.021 (0.000) | F27: =TEXT(ROUND('Mitigation Condensed'!I28,3),"0.000") & " (" & TEXT(ROUND('Mitigation Condensed'!J28,3),"0.000") & ")" -> 0.037 (0.001) | G27: =TEXT(ROUND('Mitigation Condensed'!K28,3),"0.000") & " (" & TEXT(ROUND('Mitigation Condensed'!L28,3),"0.000") & ")" -> 0.104 (0.000) | H27: =Unmitigated!C28 -> 0.18961654 | I27: =Unmitigated!D28 -> 0.18853551 | L27: 0 | M27: depth = 5 | N27: 0.106 (0.000) | O27: 0.123 (0.000) | P27: 0.094 (0.814) | Q27: 0.074 (0.000) | R27: 0.058 (0.071) | S27: 0.18708791 | T27: 0.16204223
A28: 0.5 | B28: length = 3 | C28: =TEXT(ROUND('Mitigation Condensed'!C29,3),"0.000") & " (" & TEXT(ROUND('Mitigation Condensed'!D29,3),"0.000") & ")" -> 0.104 (0.000) | D28: =TEXT(ROUND('Mitigation Condensed'!E29,3),"0.000") & " (" & TEXT(ROUND('Mitigation Condensed'!F29,3),"0.000") & ")" -> 0.123 (0.000) | E28: =TEXT(ROUND('Mitigation Condensed'!G29,3),"0.000") & " (" & TEXT(ROUND('Mitigation Condensed'!H29,3),"0.000") & ")" -> 0.022 (0.000) | F28: =TEXT(ROUND('Mitigation Condensed'!I29,3),"0.000") & " (" & TEXT(ROUND('Mitigation Condensed'!J29,3),"0.000") & ")" -> 0.039 (0.000) | G28: =TEXT(ROUND('Mitigation Condensed'!K29,3),"0.000") & " (" & TEXT(ROUND('Mitigation Condensed'!L29,3),"0.000") & ")" -> 0.092 (0.000) | H28: =Unmitigated!C29 -> 0.17936278 | I28: =Unmitigated!D29 -> 0.17621822 | L28: 0.25 | M28: depth = 5 | N28: 0.103 (0.000) | O28: 0.122 (0.000) | P28: 0.108 (0.000) | Q28: 0.073 (0.000) | R28: 0.078 (0.000) | S28: 0.18708791 | T28: 0.16204223
... A36: 0.75 | B36: depth = 9 | C36: =TEXT(ROUND('Mitigation Condensed'!C37,3),"0.000") & " (" & TEXT(ROUND('Mitigation Condensed'!D37,3),"0.000") & ")" -> 0.111 (0.000) | D36: =TEXT(ROUND('Mitigation Condensed'!E37,3),"0.000") & " (" & TEXT(ROUND('Mitigation Condensed'!F37,3),"0.000") & ")" -> 0.135 (0.000) | E36: =TEXT(ROUND('Mitigation Condensed'!G37,3),"0.000") & " (" & TEXT(ROUND('Mitigation Condensed'!H37,3),"0.000") & ")" -> 0.000 (1.000) | F36: =TEXT(ROUND('Mitigation Condensed'!I37,3),"0.000") & " (" & TEXT(ROUND('Mitigation Condensed'!J37,3),"0.000") & ")" -> 0.068 (0.000) | G36: =TEXT(ROUND('Mitigation Condensed'!K37,3),"0.000") & " (" & TEXT(ROUND('Mitigation Condensed'!L37,3),"0.000") & ")" -> 0.110 (0.000) | H36: =Unmitigated!C37 -> 0.18961654 | I36: =Unmitigated!D37 -> 0.18853551 | L36: 1 | M36: depth = 9 | N36: 0.119 (0.000) | O36: 0.142 (0.000) | P36: 0.003 (0.814) | Q36: 0.121 (0.000) | R36: 0.104 (0.000) | S36: 0.18961654 | T36: 0.18853551
A37: 0.75 | B37: length = 3 | C37: =TEXT(ROUND('Mitigation Condensed'!C38,3),"0.000") & " (" & TEXT(ROUND('Mitigation Condensed'!D38,3),"0.000") & ")" -> 0.107 (0.000) | D37: =TEXT(ROUND('Mitigation Condensed'!E38,3),"0.000") & " (" & TEXT(ROUND('Mitigation Condensed'!F38,3),"0.000") & ")" -> 0.134 (0.000) | E37: =TEXT(ROUND('Mitigation Condensed'!G38,3),"0.000") & " (" & TEXT(ROUND('Mitigation Condensed'!H38,3),"0.000") & ")" -> 0.000 (1.000) | F37: =TEXT(ROUND('Mitigation Condensed'!I38,3),"0.000") & " (" & TEXT(ROUND('Mitigation Condensed'!J38,3),"0.000") & ")" -> 0.076 (0.000) | G37: =TEXT(ROUND('Mitigation Condensed'!K38,3),"0.000") & " (" & TEXT(ROUND('Mitigation Condensed'!L38,3),"0.000") & ")" -> 0.095 (0.000) | H37: =Unmitigated!C38 -> 0.17936278 | I37: =Unmitigated!D38 -> 0.17621822
A38: 0.75 | B38: length = 5 | C38: =TEXT(ROUND('Mitigation Condensed'!C39,3),"0.000") & " (" & TEXT(ROUND('Mitigation Condensed'!D39,3),"0.000") & ")" -> 0.066 (0.000) | D38: =TEXT(ROUND('Mitigation Condensed'!E39,3),"0.000") & " (" & TEXT(ROUND('Mitigation Condensed'!F39,3),"0.000") & ")" -> 0.075 (0.000) | E38: =TEXT(ROUND('Mitigation Condensed'!G39,3),"0.000") & " (" & TEXT(ROUND('Mitigation Condensed'!H39,3),"0.000") & ")" -> 0.000 (1.000) | F38: =TEXT(ROUND('Mitigation Condensed'!I39,3),"0.000") & " (" & TEXT(ROUND('Mitigation Condensed'!J39,3),"0.000") & ")" -> 0.062 (0.000) | G38: =TEXT(ROUND('Mitigation Condensed'!K39,3),"0.000") & " (" & TEXT(ROUND('Mitigation Condensed'!L39,3),"0.000") & ")" -> 0.052 (0.138) | H38: =Unmitigated!C39 -> 0.16522865 | I38: =Unmitigated!D39 -> 0.16030497 | L38: Model | M38: L2 Median (p)
